Workbook
Name Geology: #REF!
Name Geology: #REF!
Name Geology: Geology!$D$12:$D$17
Name ListedSubstances: #REF!
Name OpenAreas: #REF!
Name OpenAreas: 'MA - Open Areas'!$D$13:$D$51
Name OpenAreas: #REF!
Name tanks: 'CWF - Fuel Tanks'!$D$11:$D$37
Name VehicleClass: 'CWF-Plant and Equipment-Diesel'!$C$94:$C$164

Sheet Title
D14: Ravenswood Gold Pty Ltd
G15: If you have any queries please contact:
D16: DATA COLLECTION SHEET | G16: Account Lead: | H16: Laura Orozco
G17: Email: | H17: lorozco@greenbase.com.au
G18: Office: | H18: (08) 9322 9966
D19: Ravenswood Operations | G19: Level 2, 41 St Georges Terrace, Perth WA | PO Box Z5451, St Georges Terrace WA 6831
D20: 01/07/2023 - 30/06/2024 | G20: Website: | H20: https://www.greenbase.com.au/
D22: Checklist | G22: Report Requirements
D24: Relevant Worksheet | E24: Responsibility | G24: NGER | H24: NPI | I24: Administration
D25: Site Attributes | E25: GC | I25: X
D26: Additional Data Entry | E26: GC | H26: X
D27: Cleaner Production | E27: GC | I27: X
D28: Feedback | E28: ALL | I28: X
D29: Production Stats | E29: GC | G29: X | I29: X
D30: Fuel Tanks | E30: CWF | H30: X | I30: X
D31: Point Source Energy | E31: CWF | G31: X | H31: X
D32: Plant and Equipment-Diesel | E32: CWF | G32: X | H32: X
D33: Plant and Equipment-Other Fuels | E33: CWF | G33: X | H33: X
D34: Drilling and Explosives | E34: ES | G34: X | H34: X
D35: Geology | E35: GC | H35: X
D36: Open Areas | E36: MA / CWF | H36: X
D37: Material Transfers | E37: GC | H37: X
D38: TSF | E38: GG / CWF | H38: X
D39: Leach Tanks and Heap Leach | E39: GG / CWF | H39: X
D40: Materials and Chemicals | E40: CWF | G40: X | H40: X
D41: Discharge | E41: GG / CWF | H41: X
D42: Spills | E42: JS | G42: X | H42: X
D43: Waste Transfers | E43: JS | H43: X
D44: Fuel Balance | E44: Greenbase | G44: X | I44: X
D46: Greenbase Service | E46: About the Reporting Program | K46: Website
D47: NPI | E47: The National Pollutant Inventory (NPI) is a pollutant release and transfer register, established by the Australian government via the National Environment Protection Measures (NEPM) legislation in 1998. The goal of the NPI is to ensure the community has access to information about the emission and transfer of toxic substances that may affect them locally in accordance with the principle of 'Community right to know'. | K47: http://www.npi.gov.au/
D48: NGER | E48: The National Greenhouse and Energy Reporting Act (NGER) was legislated by the Federal Government in 2007. The act requires companies to estimate their greenhouse gas emissions and report their energy production and energy consumption as well as other specified information. The data reported in the NGER program are used to inform government policy, inform the public, help meet Australia's international reporting obligation and assist Commonwealth, state and territory government programmes and activities. | K48: http://www.cleanenergyregulator.gov.au/Pages/default.aspx
D49: Sustainability | E49: The GRI framework is overseen by an independent organisation, and is intended to serve as a generally accepted framework for reporting an organisation's environmental, social and economic performance with a focus on rigour and quality. SASB Standards guide the disclosure of financially material sustainability information by companies to their investors. Available for 77 industries, the Standards identify the subset of environmental, social, and governance (ESG) issues most relevant to financial performance in each industry. | K49: https://www.globalreporting.org/Pages/default.aspx https://www.sasb.org/
D51: Complimentary Half Day Training | E51: Training at the Greenbase office is offered to clients as a part of the standard reporting service. This offering covers the basic understanding needed to complete reports, such as background on the NPI and NGER programmes, how to fill in the data collection templates and how to use the Greenbase system (estimated at 2 hours). | K51: https://www.greenbase.com.au/ (through secure login)
D52: Datasheet Training | E52: Training videos covering how to fill in the data collection template are available on the Greenbase website, through secure login. Please contact your Greenbase Account Lead if you do not have a login. | K52: https://www.greenbase.com.au/ (through secure login)
D54: Instructions:
E56: Note: Greenbase accepts no responsibility for the authenticity and accuracy of any numbers supplied.
D57: Cells with a | E57: white | F57: or green | H57: background require values to be entered
D58: Cells with a | E58: orange | F58: background require options to be selected from a suggested list. If a representative option is not available feel free to type in your own description
D59: Cells with a | E59: blue | F59: background require options to be selected from a suggested list, and have had an option or value entered
...

Sheet Data Source Tracking
C3: Ravenswood Operations | E3: The information in this tab will not be reported, but is rather used to record the source of data to assist with the data collection process
C4: 01/07/2023 - 30/06/2024 | E4: Examples are provided - please amend and add relevant information as applicable
C6: Data Source Tracking
C8: Tab | D8: Data Item / Parameter | E8: Frequency (e.g. monthly, quarterly, annually) | F8: Data Source | H8: Details of person collecting data | K8: Other Notes
F9: File Name | G9: Location | H9: Department | I9: Position | J9: Name
C10: Site Attributes | D10: Number of personnel
C11: Production Statistics | D11: Electricity purchased
C12: Production Statistics | D12: Ore mined
C13: Production Statistics | D13: Ore processed
C14: Production Statistics | D14: Waste mined
C15: Production Statistics | D15: Gold produced
C16: Fuel Tanks | D16: Primary tanks
C17: Fuel Tanks | D17: Service truck
C18: Point Source Energy | D18: Fuel use by other point sources
C19: Plant and Equipment - Diesel | D19: Vehicles and unmetered engines diesel use
C20: Plant and Equipment - Diesel | D20: Percent on site
C21: Plant and Equipment - Diesel | D21: Working area
... C48: Landfill | D48: Waste sent landfill
C49: [select]
C50: [select]
C51: [select]
C52: [select]
C53: [select]
C54: [select]
C55: [select]
C56: [select]
C57: [select]
C58: [select]
C59: [select]
C62: [select]
... C79: Invoices

Sheet Site Attributes
C3: Ravenswood Operations
C4: 01/07/2023 - 30/06/2024
C6: Site Attributes
C8: Personnel Employed
C9: Total number of personnel employed at site | D9: 455
C11: Weather Details
C12: Nearest BOM weather station | D12: Charters Towers Airport (034084)
C14: Facility Information
C15: Street Address | D15: 1 Macrossan Street
D16: Ravenswood, QLD
C17: Postcode | D17: 4816
C18: Environment Agency Licence No.(s) | D18: EPML00979013
C19: Other than for lighting or motive purposes is the facility's maximum power consumption ≥20MW? (1) | D19: [select]
C20: Is ≥1tonne of fuel burnt in an hour? | D20: [select]
C21: Australian New Zealand Standard Industrial Classification (ANZSIC) Code | D21: 0804 Gold Ore Mining
C23: Location
C24: Latitude (South) | D24: -20.6.45 S
C25: Longitude (East) | D25: 146.54.11 E
C27: Site Description
C32: For Public Enquires (NPI)
C33: Name | D33: Michael Limpus
C34: Management Position | D34: Environment, Approvals and Community Manager
C35: Telephone Number | D35: 07 4736 9206
C36: Postal Address | D36: PO Box 5802 Townsville, QLD
C38: Postcode | D38: 4810
C39: Public email address (if applicable) | D39: info@ravenswoodgold.com
C40: Web Address (if applicable) for hotlink from NPI internet database | D40: https://www.ravenswoodgold.com/
C42: For Technical Enquires (NPI)
C43: Name | D43: Michael Limpus
C44: Management Position | D44: Environment, Approvals and Community Manager
C45: Postal Address | D45: PO Box 5802 Townsville, QLD
C47: Postcode | D47: 4810
C48: Telephone number | D48: 07 4736 9206
C49: Email address (if applicable) | D49: info@ravenswoodgold.com
C51: Details of Facility Occupier (NPI)
C52: Name
C53: Management Position
C55: Resources Incurred (NPI)
C56: Internal Costs
C57: External Costs (Consultants, Analysis)
...

Sheet Additional Data Entry
C3: Ravenswood Operations
C4: 01/07/2023 - 30/06/2024
C6: Fuel Properties
C7: Fuel Type | D7: Density | F7: Sulphur Content
C8: Diesel | D8: 0.836 | E8: kg/L | F8: 0.001 | G8: %
C9: ULP (Gasoline) | D9: 0.735 | E9: kg/L | F9: 0.015 | G9: %
C10: LPG (Propane) | D10: 0.51 | E10: kg/L | F10: 0.01 | G10: %
C11: PNG (Natural Gas) | E11: kg/m3 | F11: 4 | G11: mg/m3
C13: Meteorological Station Data
C14: Parameter Name | F14: Value | G14: Unit | H14: Data Source
C15: Meteorological Station Name (if applicable) | F15: Nolans Weather Station | G15: Text
C16: Atmospheric pressure | F16: 10.72 | G16: kPa
C17: Climatic zone | F17: Zone 7 (North Central QLD) | G17: Option | H17: Onsite weather station at Nolans
C18: Number of rain days | F18: 56 | G18: day | H18: Onsite weather station at Nolans
C19: Wind speed | F19: 983.53 | G19: m/s | H19: Onsite weather station at Nolans
C21: Other
C22: Type | D22: Value | E22: Unit
C23: Reporting period | D23: 366 | E23: days
C25: Climatic zone
C26: [select]
C27: Zone 1 (South Central Australia)
C28: Zone 2 (South Western Australia)
C29: Zone 3 (Pilbara)
C30: Zone 4 (Top End)
C31: Zone 5 (Central Australia)
C32: Zone 6 (Cape York)
C33: Zone 7 (North Central QLD)
C34: Zone 8 (South Central QLD)
C35: Zone 9 (South QLD)
C36: Zone 10 (NSW)
... C38: Zone 12 (Tasmania)

Sheet Cleaner Production
C3: Ravenswood Operations | D3: It is optional to tick the corresponding boxes if your facility commenced any of the
C4: 01/07/2023 - 30/06/2024 | D4: source reduction techniques, however a date implemented needs to be provided.
C7: Cleaner Production Activities
D9: Used | E9: Comments
C10: Changed from solvent based to aqueous based raw materials
C11: Changed product specifications
C12: Changed production schedules to minimise equipment/feedstock changeovers
C13: Community consultative committee
C14: Dust suppression - water sprays/chemical suppression | D14: Yes | E14: Fixed plant has dust sprays installed on conveyors, crushers, screens and stockpiles. Water carts used on roadways. Water carts water down dig faces to increase moisture content of hauled material. Dust suppression chemical used in water carts.
C15: Dust suppression - wind breaks/covered/enclosed stockpiles | D15: Yes | E15: Hoods/windbreaks/scrubbers installed on transfer points. Enclosed sections on select conveyors.
C16: Implemented inspection or monitoring program for potential spill or leak sources | D16: Yes | E16: Pre-wet season preparations - ensuring bund capacity to prevent overtopping, general housekeeping, chemical storage
C17: Improved maintenance scheduling, record keeping, or procedures
C18: Improved procedures for loading, unloading or transfer operations | D18: Yes | E18: Real-time dust monitoring used to inform dust mitigation actions
C19: Installed high-pressure/low-volume cleaning equipment
C20: Installed overflow alarms or automatic shut-off valves
C21: Installed vapour recovery systems (VRS)
C22: Modified packaging
C23: Modified process, equipment, layout, or piping | E23: Dust collector on BRW crusher - GC confirm with Pual Botman.
C24: Use of cleaner raw materials
C25: Other modifications/practices (please specify)
C28: Installation of Pollution Control Equipment
D30: Used | E30: Year Installed | F30: Comments
C31: Activated carbon filter
C32: Bio scrubber
C33: Biofilter
C34: Cyclone/mutlicyclone
C35: Dry scrubber
C36: Dust monitor | D36: Yes | E36: 2017, 2018, 2020 | F36: Dust monitors are used to collect real-time data and inform dust mitigation actions. PM10 BAM installed 2017, PM2.5 BAM and TSP installed 2018, second PM10 BAM installed 2020.
C37: Electrostatic Precipitator
C38: Fabric filter/baghouse
C39: Incineration/afterburner
C40: Low NOx burner
C41: Mist eliminator
C42: Opacity monitor
C43: Thermal oxidiser
C44: Wastewater treatment
C45: Wet scrubber
C46: Other (please specify)

Sheet Feedback
C3: Ravenswood Operations | G3: This tab is used to record the queries and data sent between site and the Greenbase Account Lead to support the data during audits
C4: 01/07/2023 - 30/06/2024
C6: Feedback
C8: Questions/Queries
C10: Item No. | D10: Date | E10: Tab | F10: Raised By | G10: Query Raised | H10: Response Date | I10: Query Response By | J10: Query Response | K10: Status
C28: Raw Datasheet References
D30: Date | E30: Tab | F30: Sent By | G30: Description of Raw Data | H30: Cell Reference
C40: Phone Call Logs
D42: Date & Time | E42: Caller | F42: Recipient | G42: Description of Phone Call

Sheet GC - Production Stats
C3: Ravenswood Operations | E3: Method: Production Statistics Data: E-mail Rebecca.Caswell@ravenswooggold.com and ask for the "Operations and Metrics" excel file for the FY. The sheet runs off a calendar year, so you will need both the preceding and current years' sheets. refer to the "Data Source/Supplier" column below to find and copy/paste the relevant data from the Operations and Metrics excel file. Ergon & CS Energy Data: E-mail Carole.Anderson@ravenswoodgold.com to obtain the Ergon and CS Energy invoices for the FY. Open each invoice and find the kWh for each month (include both Tarrif 11 and Tariff 33). Make note of any properties which have solar, as well as the solar contribution, in a comment. NPE Dredge & Power Station Data: E-mail RGL.PowerstationOps@nationalpump.com.au the data table for the dredge and power station and ask if they can fill out each months' kWh, as well as send through the log sheet for data QAQC. Brisbane office: e-mail louise.mettam-minas@ravenswoodgold.com and ask if she can send through the Brisbane office invoices, which include the power use.
C4: 01/07/2023 - 30/06/2024
E5: Grey cells are residential, so are excluded from NGERS reporting (outside operational control)
C6: Production Statistics
H7: Monthly Total
D8: Data Source/ Supplier | E8: FY2023 | F8: FY2024 | G8: Unit | H8: Jul | I8: Aug | J8: Sep | K8: Oct | L8: Nov | M8: Dec | N8: Jan | O8: Feb | P8: Mar | Q8: Apr | R8: May | S8: Jun
C9: High Grade Ore Mined (BRW) | D9: Intranet --> Monthly Sheet --> Month End --> 7. Jul 24 --> Operations and Metrics Jul 24-Site.xlsx/Input-R/Mining/ | E9: 7347387.1 | F9: =SUM(H9:S9) -> 5776718.7 | G9: Dry Tonnes | H9: =SUM(H73, H75) -> 515235.55 | I9: =SUM(I73, I75) -> 763533.16 | J9: =SUM(J73, J75) -> 817076.15 | K9: =SUM(K73, K75) -> 354957.75 | L9: =SUM(L73, L75) -> 475054.76 | M9: =SUM(M73, M75) -> 331188.76 | N9: =SUM(N73, N75) -> 284776.63 | O9: =SUM(O73, O75) -> 394157.33 | ... S9: =SUM(S73, S75) -> 140308.49
C10: Medium Grade Ore Mined (BRW) | D10: Intranet --> Monthly Sheet --> Month End --> 7. Jul 24 --> Operations and Metrics Jul 24-Site.xlsx/Input-R/Mining/ | E10: - | F10: =SUM(H10:S10) -> 1148492.6 | G10: Dry Tonnes | H10: =H76 -> 0 | I10: =I76 -> 0 | J10: =J76 -> 0 | K10: =K76 -> 0 | L10: =L76 -> 0 | M10: =M76 -> 0 | N10: =N76 -> 133648.03 | O10: =O76 -> 118494.18 | ... S10: =S76 -> 331457.05
C11: Low Grade Ore Mined (BRW) | D11: Intranet --> Monthly Sheet --> Month End --> 7. Jul 24 --> Operations and Metrics Jul 24-Site.xlsx/Input-R/Mining/ | E11: 4630014 | F11: =SUM(H11:S11) -> 3252665.2 | G11: Dry Tonnes | H11: =SUM(H74, H77) -> 354642.03 | I11: =SUM(I74, I77) -> 406755.88 | J11: =SUM(J74, J77) -> 425750.19 | K11: =SUM(K74, K77) -> 410280 | L11: =SUM(L74, L77) -> 427113.79 | M11: =SUM(M74, M77) -> 374721.4 | N11: =SUM(N74, N77) -> 182972.36 | O11: =SUM(O74, O77) -> 147451.87 | ... S11: =SUM(S74, S77) -> 47793.416
C12: Very Low Grade Ore Mined (BRW) | D12: Intranet --> Monthly Sheet --> Month End --> 7. Jul 24 --> Operations and Metrics Jul 24-Site.xlsx/Input-R/Mining/ | E12: - | F12: =SUM(H12:S12) -> 522039.19 | G12: Dry Tonnes | H12: =H78 -> 0 | I12: =I78 -> 0 | J12: =J78 -> 0 | K12: =K78 -> 0 | L12: =L78 -> 0 | M12: =M78 -> 0 | N12: =N78 -> 32524.695 | O12: =O78 -> 90539.6 | ... S12: =S78 -> 177821.5
C13: High Grade Ore Mined (SAR) | D13: Intranet --> Monthly Sheet --> Month End --> 7. Jul 24 --> Operations and Metrics Jul 24-Site.xlsx/Input-R/Mining/ | E13: 7347387.1 | F13: =SUM(H13:S13) -> 0 | G13: Dry Tonnes | H13: =H79 | I13: =I79 -> - | J13: =J79 | K13: =K79 | L13: =L79 | M13: =M79 | N13: =N79 -> - | O13: =O79 -> - | ... S13: =S79 -> -
C14: Medium Grade Ore Mined (SAR) | D14: Intranet --> Monthly Sheet --> Month End --> 7. Jul 24 --> Operations and Metrics Jul 24-Site.xlsx/Input-R/Mining/ | E14: - | F14: =SUM(H14:S14) -> 212868.1 | G14: Dry Tonnes | H14: =H80 -> 0 | I14: =I80 -> 0 | J14: =J80 -> 0 | K14: =K80 -> 0 | L14: =L80 -> 0 | M14: =M80 -> 0 | N14: =N80 -> 117570.79 | O14: =O80 -> 32018.227 | ... S14: =S80 -> -
C15: Low Grade Ore Mined (SAR) | D15: Intranet --> Monthly Sheet --> Month End --> 7. Jul 24 --> Operations and Metrics Jul 24-Site.xlsx/Input-R/Mining/ | E15: 4630014 | F15: =SUM(H15:S15) -> 477907.8 | G15: Dry Tonnes | H15: =H81 -> 0 | I15: =I81 -> 8272.8764 | J15: =J81 -> 0 | K15: =K81 -> 65093.641 | L15: =L81 -> 28024.093 | M15: =M81 -> 88405.763 | N15: =N81 -> 51172.795 | O15: =O81 -> 30482.235 | ... S15: =S81 -> 77072.854
C16: Very Low Grade Ore Mined (SAR) | D16: Intranet --> Monthly Sheet --> Month End --> 7. Jul 24 --> Operations and Metrics Jul 24-Site.xlsx/Input-R/Mining/ | E16: - | F16: =SUM(H16:S16) -> 233878.8 | G16: Dry Tonnes | H16: =H82 -> 0 | I16: =I82 -> 0 | J16: =J82 -> 0 | K16: =K82 -> 0 | L16: =L82 -> 0 | M16: =M82 -> 0 | N16: =N82 -> - | O16: =O82 -> - | ... S16: =S82 -> -
C17: Ore Mined | D17: Intranet --> Monthly Sheet --> Month End --> 7. Jul 24 --> Operations and Metrics Jul 24-Site.xlsx/Input-R/Mining/Open Pit Ore Mined (t) | E17: 11728016 | F17: =SUM(H17:S17) -> 11624570 | G17: Dry Tonnes | H17: 869878 | I17: 1178562 | J17: 1242826 | K17: 830331 | L17: 930193 | M17: 794316 | N17: 802665 | O17: 813143 | P17: 924674 | Q17: 1144807 | R17: 1318722 | S17: 774453
C18: Waste Mined | D18: Intranet --> Monthly Sheet --> Month End --> 7. Jul 24 --> Operations and Metrics Jul 24-Site.xlsx/Input-R/Mining/Total Waste Mined (t) | E18: 20832862 | F18: =SUM(H18:S18) -> 18559743 | G18: Dry Tonnes | H18: =H85 -> 1491689 | I18: =I85 -> 1285904 | J18: =J85 -> 1254104 | K18: =K85 -> 2044595 | L18: =L85 -> 1816547 | M18: =M85 -> 1880825 | N18: =N85 -> 1684063 | O18: =O85 -> 1629074 | ... S18: =S85 -> 1700313
C19: Ore Processed | D19: Intranet --> Monthly Sheet --> Month End --> 7. Jul 24 --> Operations and Metrics Jul 24-Site.xlsx/Input-R/Milling/Ore Milled (t) | E19: 5083091.4 | F19: =SUM(H19:S19) -> 7099788 | G19: Dry Tonnes | H19: =H88 -> 598983 | I19: =I88 -> 527565 | J19: =J88 -> 537161 | K19: =K88 -> 685313 | L19: =L88 -> 567254 | M19: =M88 -> 660870 | N19: =N88 -> 584835 | O19: =O88 -> 567444 | ... S19: =S88 -> 565189
C20: Waste Moved | D20: Greenbase | E20: 20832862 | F20: =SUM(H20:S20) -> 0 | G20: Dry Tonnes
C21: Ore Moved | D21: Greenbase | F21: =SUM(H21:S21) -> 0 | G21: Tonne
C23: Total Gold Produced | D23: Intranet --> Monthly Sheet --> Month End --> 7. Jul 24 --> Operations and Metrics Jul 24-Site.xlsx/Input-R/Milling/Gold Poured (oz.) | E23: 149454.17 | F23: =SUM(H23:S23) -> 176597 | G23: Troy oz | H23: =H91 -> 9772 | I23: =I91 -> 14285 | J23: =J91 -> 15721 | K23: =K91 -> 19981 | L23: =L91 -> 15809 | M23: =M91 -> 14479 | N23: =N91 -> 18770 | O23: =O91 -> 11814 | ... S23: =S91 -> 14028
C25: Electricity Purchased
H26: Monthly Total
D27: Data Source/ Supplier | E27: Residential or business | F27: Annual | G27: units | H27: Jul | I27: Aug | J27: Sep | K27: Oct | L27: Nov | M27: Dec | N27: Jan | O27: Feb | P27: Mar | Q27: Apr | R27: May | S27: Jun
C28: Electricity Purchased | D28: ERGON NMI: 30337828149 (91214562) - 19 Robert St (STP) (G:Accounting\End of Month\20## End of Month\##. MMM YY) | E28: Business | F28: =SUM(H28:S28) -> 185520.64 | G28: kWh | H28: 15955 | I28: =6422.9+7706 -> 14128.9 | J28: 13966.63 | K28: 16022.11 | L28: 15163.58 | M28: 16411.075 | N28: 16009.47 | O28: 16750.14 | P28: 15238.06 | Q28: 15501.12 | R28: 14598.63 | S28: 15775.92
D29: ERGON NMI: 30518901604 (91610919) - Sandy Creek Rd (G:Accounting\End of Month\20## End of Month\##. MMM YY) | E29: Business | F29: =SUM(H29:S29) -> 884301.7 | G29: kWh | H29: 46284.1 | I29: 43853.9 | J29: 66521.2 | K29: 63617.3 | L29: 67446 | M29: 58857.9 | N29: 61401.8 | O29: 88620 | P29: =116041.6 -> 116041.6 | Q29: =81440.6 -> 81440.6 | R29: =102324.4 -> 102324.4 | S29: =87892.9 -> 87892.9
D30: ERGON NMI: 30500014267 (91010964) - Suhrs Creek Rd (SCD) (G:Accounting\End of Month\20## End of Month\##. MMM YY) | E30: Business | F30: =SUM(H30:S30) -> 788709.66 | G30: kWh | H30: 65569.91 | I30: 66904.72 | J30: 63446.84 | K30: 66641.5 | L30: 59701.31 | M30: 59809 | N30: 61286.44 | O30: 56406.98 | P30: 0 | Q30: 134725.1 | R30: =79806.74 -> 79806.74 | S30: 74411.12
D31: ERGON NMI: 3053093335 (217041068) 11 ELLIOTT ST | E31: Business | F31: =SUM(H31:S31) -> 3486.879 | G31: kWh | H31: 276.57 | I31: 261.48 | J31: 233.66 | K31: 312.17 | L31: 332.749 | M31: 336.1 | N31: 318.74 | O31: 289.02 | P31: 471.52 | Q31: 278.08 | R31: 266.64 | S31: 110.15
D32: ERGON NMI: 3033782881 (90301081) SANDY CK ROAD | E32: Business | F32: =SUM(H32:S32) -> 72726.88 | G32: kWh | H32: =1082.92+3829.79+2067.43 -> 6980.14 | I32: =1269.66+4037.99+2312.8 -> 7620.45 | J32: 7851.18 | K32: 8449.87 | L32: 7537.37 | M32: 6538.92 | N32: 6360.23 | O32: 5512.79 | P32: =1022.38+1790.62+3227.69 -> 6040.69 | Q32: =1001.23+1714.3+3205.29 -> 5920.82 | R32: =300.93+580.81+1116.11 -> 1997.85 | S32: =265.58+556.99+1094 -> 1916.57
D33: ERGON NMI: 30337828651 - 20 TOWNSVILLE ST | E33: Residential | F33: =SUM(H33:S33) -> 9623.62 | G33: kWh | H33: 586.62 | I33: 0 | J33: 0 | K33: 0 | L33: 2394 | M33: 0 | N33: 0 | O33: 3187 | P33: 0 | Q33: 0 | R33: =3017+439 -> 3456 | S33: 0
D34: ERGON NMI: 30337829971 - 23 SCOTIA ST | E34: Residential | F34: =SUM(H34:S34) -> 9691.4 | G34: kWh | H34: 570.4 | I34: 0 | J34: 0 | K34: 0 | L34: 2319 | M34: 0 | N34: 0 | O34: 3589 | P34: 0 | Q34: 0 | R34: 3213 | S34: 0
D35: ERGON NMI: 3034225404 - 26 SCOTIA ST | E35: Residential | F35: =SUM(H35:S35) -> 9578.77 | G35: kWh | H35: 876.77 | I35: 0 | J35: 0 | K35: 0 | L35: 2001 | M35: 0 | N35: 0 | O35: 3404 | P35: 0 | Q35: 0 | R35: 3297 | S35: 0
D36: ERGON NMI: 30337863212 - 5 CECIL ST | E36: Residential | F36: =SUM(H36:S36) -> 6812.53 | G36: kWh | H36: 924.53 | I36: 0 | J36: 0 | K36: 0 | L36: 2556 | M36: 0 | N36: 0 | O36: 0 | P36: 0 | Q36: 0 | R36: 3332 | S36: 0
D37: ERGON NMI: 30337764822 - SANDY CK RD | E37: Business | F37: =SUM(H37:S37) -> 2690.68 | G37: kWh | H37: 218.68 | I37: 0 | J37: 0 | K37: 0 | L37: 828 | M37: 0 | N37: 0 | O37: 1042 | P37: 0 | Q37: 0 | R37: 602 | S37: 0
D38: ERGON NMI: 30337850079 - 28 SCOTIA ST | E38: Residential | F38: =SUM(H38:S38) -> 11739.631 | G38: kWh | H38: =166.19+153.59 -> 319.78 | I38: =280.89+446.48 -> 727.37 | J38: =161.333+531.474 -> 692.807 | K38: 760.92 | L38: 1156.86 | M38: 1324.63 | N38: 1578.58 | O38: 1301.554 | P38: 1942.74 | Q38: =121.94+787.72 -> 909.66 | R38: =545.31+172.08 -> 717.39 | S38: =89.24+218.1 -> 307.34
D39: ERGON NMI: 3033785104 - DEIGHTON ST | E39: Business | F39: =SUM(H39:S39) -> 23485.57 | G39: kWh | H39: 3092.57 | I39: 0 | J39: 0 | K39: 0 | L39: 6700 | M39: 0 | N39: 0 | O39: 7079 | P39: 0 | Q39: 0 | R39: 6614 | S39: 0
D40: ERGON NMI: 30337830121 - 12 TOWNSVILLE ST | E40: Residential | F40: =SUM(H40:S40) -> 5894.05 | G40: kWh | H40: 496.05 | I40: 0 | J40: 0 | K40: 0 | L40: 2464 | M40: 0 | N40: 0 | O40: 2934 | P40: 0 | Q40: 0 | R40: 0 | S40: 0
D41: ERGON NMI: 3033786267 - 69 MURRAY ST | E41: Residential | F41: =SUM(H41:S41) -> 16702.96 | G41: kWh | H41: 373.96 | I41: 0 | J41: 0 | K41: 0 | L41: 964 | M41: 0 | N41: 0 | O41: 3148 | P41: 0 | Q41: 0 | R41: 12217 | S41: 0
D42: ERGON NMI: 3034101161 - LONDON ST | E42: Business | F42: =SUM(H42:S42) -> 1453.96 | G42: kWh | H42: 250.96 | I42: 0 | J42: 0 | K42: 0 | L42: 354 | M42: 0 | N42: 0 | O42: 426 | P42: 0 | Q42: 0 | R42: 423 | S42: 0
D43: ERGON NMI: 3033782831 - 18 TOWNSVILLE ST | E43: Residential | F43: =SUM(H43:S43) -> 6245.19 | G43: kWh | H43: 235.19 | I43: 0 | J43: 0 | K43: 0 | L43: 1418 | M43: 0 | N43: 0 | O43: 2602 | P43: 0 | Q43: 0 | R43: 1990 | S43: 0
D44: ERGON NMI: 3033783021 - 25 SCOTIA ST | E44: Residential | F44: =SUM(H44:S44) -> 9188.32 | G44: kWh | H44: 589.32 | I44: 0 | J44: 0 | K44: 0 | L44: 2210 | M44: 0 | N44: 0 | O44: 2168 | P44: 0 | Q44: 0 | R44: 4221 | S44: 0
...

Sheet CWF - Fuel Tanks
C3: Ravenswood Operations | K3: Enter all tanks that have been used during the year. Volatilisation from tanks can be a significant source of hydrocarbon related substances to the atmosphere. Where tanks are not Fixed Roof Storage, please specify
C4: 01/07/2023 - 30/06/2024 | K4: Diesel which is loaded into a fuel pod on a service truck should be entered as a secondary tank
K5: Once you have the fuel database data from Carole, group the data for each tank (e.g., "POD 851837"), then create a pivot table to determine the fuel use for each tank. Update the values in red.
C6: Diesel Storage in Fixed Roof Storage Tanks
L7: Data Sources: | N7: RG Fuel Database - Carole, Fuel invoices - Julie/Carole (need these for QAQC)
D9: Tank name or code number | E9: Fuel Type | F9: FY2023 Throughput | G9: FY2024 Throughput | I9: FY2023 Deliveries | J9: FY2024 Deliveries | K9: Unit | L9: Jul Opening Balance | N9: Monthly Deliveries | AA9: Jun Closing Balance | AC9: Orientation/ Buried | AD9: Capacity | AE9: Unit
N10: Jul | O10: Aug | P10: Sep | Q10: Oct | R10: Nov | S10: Dec | T10: Jan | U10: Feb | V10: Mar | W10: Apr | X10: May | Y10: Jun
C11: Primary Tanks | D11: Sarsfield (self-bunded) | E11: Diesel | F11: 24346568 | G11: =J11+L11 -> 24165678 | I11: 24244168 | J11: =SUM(N11:Y11) -> 24159478 | K11: L | L11: 6200 | N11: 2007687 | O11: 1863936 | P11: 1986870 | Q11: 1970499 | R11: 2139412 | S11: 2062816 | T11: 2077029 | U11: 1842639 | V11: 2043938 | W11: 2171280 | X11: 2099708 | Y11: 1893664 | AA11: 108000 | AC11: Horizontal | AD11: =54000+69600 -> 123600 | AE11: L
D12: Nolans Diesel Tank | E12: Diesel | F12: 259559 | G12: =J12+L12 -> 293555 | I12: 255109 | J12: =SUM(N12:Y12) -> 285855 | K12: L | L12: 7700 | N12: 27548 | O12: 18168 | P12: 21215 | Q12: 22469 | R12: 21751 | S12: 16001 | T12: 31992 | U12: 24981 | V12: 30872 | W12: 23173 | X12: 24048 | Y12: 23637 | AA12: 6800 | AC12: Horizontal | AD12: 15000 | AE12: L
D13: Pensar | E13: Diesel | F13: 1205284 | G13: =J13+L13 -> 1511138 | I13: 1170184 | J13: =SUM(N13:Y13) -> 1469438 | K13: L | L13: 41700 | N13: 67979 | O13: 75232 | P13: 58375 | Q13: 166677 | R13: 125571 | S13: 92463 | T13: 139506 | U13: 111511 | V13: 165707 | W13: 197452 | X13: 142483 | Y13: 126482 | AA13: 48000 | AC13: Horizontal | AD13: 65570 | AE13: L
D14: RG Power Station | E14: Diesel | F14: 17614711 | G14: =J14+L14 -> 24736632 | I14: 17493811 | J14: =SUM(N14:Y14) -> 24391382 | K14: L | L14: 345250 | N14: 1913069 | O14: 1478560 | P14: 1846962 | Q14: 2390616 | R14: 2212561 | S14: 2236883 | T14: 2018078 | U14: 2024285 | V14: 1660743 | W14: 2388446 | X14: 2161047 | Y14: 2060132 | AA14: 68000 | AC14: Horizontal | AD14: 124000 | AE14: L
E15: Diesel | G15: =J15+L15 -> 0 | J15: =SUM(N15:Y15) -> 0 | K15: [select] | AC15: [select] | AE15: [select]
E16: Diesel | G16: =J16+L16 -> 0 | J16: =SUM(N16:Y16) -> 0 | K16: [select] | AC16: [select] | AE16: [select]
C18: Total Deliveries | F18: 43426122 | G18: =SUM(G11:G16) -> 50707003 | I18: 43163272 | J18: =SUM(J11:J16) -> 50306153 | L18: =SUM(L11:L16) -> 400850 | N18: =SUM(N11:N16) -> 4016283 | O18: =SUM(O11:O16) -> 3435896 | P18: =SUM(P11:P16) -> 3913422 | Q18: =SUM(Q11:Q16) -> 4550261 | R18: =SUM(R11:R16) -> 4499295 | S18: =SUM(S11:S16) -> 4408163 | T18: =SUM(T11:T16) -> 4266605 | U18: =SUM(U11:U16) -> 4003416 | ... Y18: =SUM(Y11:Y16) -> 4103915 | AA18: =SUM(AA11:AA16) -> 230800
C20: Secondary Tanks | D20: Eagle Drilling Fuel Pod | E20: Diesel | F20: 35268.61 | G20: =J20+L20 -> 51429.04 | I20: 35268.61 | J20: =SUM(N20:Y20) -> 51429.04 | K20: L | Q20: 7942.14 | R20: 15976.63 | U20: 15038.21 | V20: 6665.18 | W20: 3249.15 | X20: =132.33+66.75 -> 199.08 | Y20: 2358.65 | AC20: Horizontal | AE20: [select]
D21: Fuel Pods | E21: Diesel | F21: 373615.77 | G21: =J21+L21 -> 206178.19 | I21: 373615.77 | J21: =SUM(N21:Y21) -> 206178.19 | K21: L | N21: =5164.81+1260.72+186.9+321.63 -> 6934.06 | O21: =399.27+265.54+898.51+6063+228.79+770.57 -> 8625.68 | P21: =109.74+440+843.48+186.56+179.62+199.14+327.51+244.93+217.54+5811.69 -> 8560.21 | Q21: =1697 -> 1697 | R21: =2042.29+401.55+216.73+430 -> 3090.57 | S21: =1356.79+403.3+53.73+308.46 -> 2122.28 | T21: =1661.73+3175+35+308.41 -> 5180.14 | U21: =1337.77+4750+12.63+305.53+3962.34 -> 10368.27 | V21: =310+7765+2680.29+39.27+358.92+3220+783.76+1134.17+1343.6 -> 17635.01 | W21: =22442+4724.68+410.2+297.98+1940+4550+3315+2862.67 -> 40542.53 | X21: =23736+16690+6961.16+197.91+135.84+2510+280+9900+1180+2950+137.92 -> 64678.83 | Y21: =27277+787.61+1520+5759+1400 -> 36743.61 | AC21: Horizontal | AE21: [select]
D22: POD 851837 NPE | E22: Diesel | F22: 72196 | G22: =J22+L22 -> 212687 | I22: 72196 | J22: =SUM(N22:Y22) -> 212687 | K22: L | N22: 13635 | O22: 14920 | P22: 11290 | Q22: 12128 | R22: 10280 | S22: 9497 | T22: 17966 | U22: 13706 | V22: 23280 | W22: 39455 | X22: 24480 | Y22: 22050 | AC22: Horizontal | AE22: [select]
D23: POD 851839 NPE | E23: Diesel | F23: 108456 | G23: =J23+L23 -> 303158 | I23: 108456 | J23: =SUM(N23:Y23) -> 303158 | K23: L | N23: 15930 | O23: 13690 | P23: 22530 | Q23: 13640 | R23: 18980 | S23: 17847 | T23: 28683 | U23: 22220 | V23: 32640 | W23: 53115 | X23: 37153 | Y23: 26730 | AC23: Horizontal | AE23: [select]
D24: POD 851828 NPE | E24: Diesel | F24: 55922 | G24: =J24+L24 -> 158141.61 | I24: 55922 | J24: =SUM(N24:Y24) -> 158141.61 | K24: L | N24: 8128 | O24: 7970 | P24: 9871.61 | Q24: 9734 | R24: 10610 | S24: 9198 | T24: 17477 | U24: 8980 | V24: 16995 | W24: 22225 | X24: 19290 | Y24: 17663 | AC24: Horizontal | AE24: [select]
D25: POD/PUMP 554404 | E25: Diesel | F25: 21418 | G25: =J25+L25 -> 12510 | I25: 21418 | J25: =SUM(N25:Y25) -> 12510 | K25: L | N25: 910 | O25: 1680 | P25: 580 | Q25: 1111 | R25: 2079 | S25: 1290 | T25: 480 | U25: 2300 | V25: 2080 | AC25: Horizontal | AE25: [select]
D26: RMS BULK TANK | E26: Diesel | F26: 150939.1 | G26: =J26+L26 -> 0 | I26: 150939.1 | J26: =SUM(N26:Y26) -> 0 | K26: L | AC26: Horizontal | AE26: [select]
D27: ST522 | E27: Diesel | F27: 300 | G27: =J27+L27 -> 0 | I27: 300 | J27: =SUM(N27:Y27) -> 0 | K27: L | AC27: Horizontal | AE27: [select]
D28: ST551 | E28: Diesel | F28: 118825.36 | G28: =J28+L28 -> 147354.9 | I28: 118825.36 | J28: =SUM(N28:Y28) -> 147354.9 | K28: L | N28: 630 | O28: 830 | P28: 730 | Q28: 380 | R28: 600 | S28: 540 | T28: 780 | U28: 110 | V28: 142276.98 | W28: 340 | X28: 137.92 | AC28: Horizontal | AE28: [select]
D29: ST08 | E29: Diesel | F29: 11916.57 | G29: =J29+L29 -> 0 | I29: 11916.57 | J29: =SUM(N29:Y29) -> 0 | K29: L | AC29: Horizontal | AE29: [select]
D30: SDH67 TRAILER POD DYNA - SDH67 | E30: Diesel | F30: 38192.95 | G30: =J30+L30 -> 222.39 | I30: 38192.95 | J30: =SUM(N30:Y30) -> 222.39 | K30: L | V30: 222.39 | AC30: Horizontal | AE30: [select]
D31: TK200 12000LT BULK TANK - CIRCUIT 1 | E31: Diesel | F31: 98401.3 | G31: =J31+L31 -> 0 | I31: 98401.3 | J31: =SUM(N31:Y31) -> 0 | K31: L | AC31: Horizontal | AE31: [select]
D32: TK201 DIESEL FUEL POD | E32: Diesel | F32: 91575.63 | G32: =J32+L32 -> 185350.28 | I32: 91575.63 | J32: =SUM(N32:Y32) -> 185350.28 | K32: L | N32: 13094.55 | O32: 20549.33 | P32: 20480.13 | Q32: 17091.97 | R32: 22693.51 | S32: 11976.27 | T32: 28764.91 | U32: 12881.22 | V32: 15306.38 | W32: 13172.45 | X32: 8454.16 | Y32: 885.4 | AC32: Horizontal | AE32: [select]
D33: SDH85 POD - 686HBQ | E33: Diesel | F33: 4045.62 | G33: =J33+L33 -> 2258.25 | I33: 4045.62 | J33: =SUM(N33:Y33) -> 2258.25 | K33: L | P33: 2258.25 | AC33: Horizontal | AE33: [select]
D34: ST801 SPARE 30,000L FILL FOB - ST801 | E34: Diesel | F34: 184057.9 | G34: =J34+L34 -> 76479.25 | I34: 184057.9 | J34: =SUM(N34:Y34) -> 76479.25 | K34: L | N34: 6458.7 | O34: 3995.9 | P34: 2049.5 | Q34: 7368.3 | R34: 1774.1 | S34: 8499.8 | T34: 37668.95 | U34: 4923.2 | V34: 1336.6 | W34: 1361.1 | X34: 665.5 | Y34: 377.6 | AC34: Horizontal | AE34: [select]
D35: ST04 Roc-Drill | E35: Diesel | G35: =J35+L35 -> 1165807.7 | J35: =SUM(N35:Y35) -> 1165807.7 | K35: L | N35: 110233.93 | O35: 108477.17 | P35: 130024.08 | Q35: 155403.16 | R35: 168922.7 | S35: 136532.41 | T35: 143072.07 | U35: 127175.18 | V35: 56592.34 | W35: 27427.02 | X35: 1368.06 | Y35: 579.53 | AC35: [select] | AE35: [select]
D36: ST550 | E36: Diesel | G36: =J36+L36 -> 0 | J36: =SUM(N36:Y36) -> 0 | K36: L | AC36: [select] | AE36: [select]
D37: Pensar Fuel Pod 022A23 | E37: Diesel | G37: =J37+L37 -> 62907.38 | J37: =SUM(N37:Y37) -> 62907.38 | K37: L | S37: 62907.38 | AC37: [select] | AE37: [select]
C39: Total Secondary Tank Throughput | F39: 1365130.8 | G39: =SUM(G20:G37) -> 2584483.9 | I39: 1365130.8 | J39: =SUM(J20:J37) -> 2584483.9 | L39: =SUM(L20:L37) -> 0 | N39: =SUM(N20:N37) -> 175954.24 | O39: =SUM(O20:O37) -> 180738.08 | P39: =SUM(P20:P37) -> 208373.78 | Q39: =SUM(Q20:Q37) -> 226495.57 | R39: =SUM(R20:R37) -> 255006.51 | S39: =SUM(S20:S37) -> 260410.14 | T39: =SUM(T20:T37) -> 280072.07 | U39: =SUM(U20:U37) -> 217702.08 | ... Y39: =SUM(Y20:Y37) -> 107387.79 | AA39: =SUM(AA20:AA37) -> 0
C41: Other Fuel Tanks
C43: Other Fuel Tanks | D43: ULP Tank | E43: ULP | G43: =J43+L43 -> 0 | J43: =SUM(N43:Y43) -> 0 | K43: [select] | AC43: [select] | AE43: [select]
E44: [select] | G44: =J44+L44 -> 0 | J44: =SUM(N44:Y44) -> 0 | K44: [select] | AC44: [select] | AE44: [select]
E45: [select] | G45: =J45+L45 -> 0 | J45: =SUM(N45:Y45) -> 0 | K45: [select] | AC45: [select] | AE45: [select]
E46: [select] | G46: =J46+L46 -> 0 | J46: =SUM(N46:Y46) -> 0 | K46: [select] | AC46: [select] | AE46: [select]
C49: All fuel storage tanks that have a breather vent must be recorded
C50: Primary tanks have fuel delivered directly from the fuel supplier. A secondary tank only receives fuel from the primary tank. Total fuel use on site is aggregated from primary tanks only to avoid double counting
...

Sheet CWF - Point Source Energy
C3: Ravenswood Operations | G3: Enter all power generators (>500kW) and other sources of point souce emissions
C4: 01/07/2023 - 30/06/2024 | G4: Point source emissions are directed into a vent or stack and emitted through a single point source into the atmosphere.
C6: Point Source Energy - Fuel Use and Electricity Production
G8: Data Source: | I8: Pronto - Stock Issues 103570 (772256) (talk to Murray to get an export of stock issues from Pronto), created pivot table to identify monthly Qty of LPG. Used allocation ratio to determine how much LPG each plant item uses. Origin Energy - bulk supplied (get invoices for this from Julie/Carole - we need the invoices for QAQC),
C9: Process Heating
I10: Fuel Used | V10: Allocation Ratio (%)
C11: Class | D11: Name | E11: Fuel Type (1) | F11: FY2023 Fuel | G11: FY2024 Fuel | H11: Unit | I11: Jul | J11: Aug | K11: Sep | L11: Oct | M11: Nov | N11: Dec | O11: Jan | P11: Feb | Q11: Mar | R11: Apr | S11: May | T11: Jun
C12: Boilers | D12: Glycol Boiler | E12: LPG | F12: 186204.4 | G12: =SUM(I12:T12) -> 337493 | H12: L | I12: 21014 | J12: 31361 | K12: 22777 | L12: 16468 | M12: 39135 | N12: 16406 | O12: 29568 | P12: 21210 | Q12: 42641 | R12: 29445 | S12: 26528 | T12: 40940 | V12: 50
C13: Furnaces | D13: Gold Room Furnace | E13: LPG | F13: 18620.44 | G13: =SUM(I13:T13) -> 33750 | H13: L | I13: 2101 | J13: 3136 | K13: 2278 | L13: 1647 | M13: 3914 | N13: 1641 | O13: 2957 | P13: 2121 | Q13: 4264 | R13: 2944 | S13: 2653 | T13: 4094 | V13: 5
C14: Furnaces | D14: Laboratory Muffle Furnace | E14: LPG | F14: 18620.44 | G14: =SUM(I14:T14) -> 33750 | H14: L | I14: 2101 | J14: 3136 | K14: 2278 | L14: 1647 | M14: 3914 | N14: 1641 | O14: 2957 | P14: 2121 | Q14: 4264 | R14: 2944 | S14: 2653 | T14: 4094 | V14: 5
C15: Kilns | D15: Kilns/Boilers (Gold Processing) | E15: LPG | F15: 148963.52 | G15: =SUM(I15:T15) -> 269996 | H15: L | I15: 16812 | J15: 25089 | K15: 18222 | L15: 13174 | M15: 31308 | N15: 13125 | O15: 23654 | P15: 16968 | Q15: 34113 | R15: 23556 | S15: 21223 | T15: 32752 | V15: 40
E16: [select] | H16: [select]
E17: [select] | H17: [select]
C19: Total LPG Usage | E19: LPG | F19: 372408.8 | G19: =SUM(I19:T19) -> 674986.9 | H19: L | I19: 42028.9 | J19: 62722.7 | K19: 45553.9 | L19: 32935.2 | M19: 78270.2 | N19: 32812.2 | O19: 59135.1 | P19: 42420.6 | Q19: 85282.6 | R19: 58889.8 | S19: 53056.5 | T19: 81879.2 | V19: =SUM(V12:V17) -> 100
C21: Pollution Control
C22: Class | D22: Name | E22: Engine Power Rating (kW) | F22: Pollution Control, please list | G22: Date Installed | H22: Total Operating Hours | I22: Unit Type/Size?
C23: Other Point Source | D23: Glycol Boiler | E23: 1500 | F23: None | I23: LPG (N/A)
D24: Gold Room Furnace | E24: 30 | F24: None | I24: LPG (N/A)
D25: Laboratory Muffle Furnace | E25: 30 | F25: None | I25: LPG (N/A)
D26: Kilns/Boilers (Gold Processing) | E26: 350 | F26: None | I26: LPG (N/A)
F27: [select] | I27: [select]
F28: [select] | I28: [select]
C30: Other Unit Size | D30: Other Point Source | E30: Engine
C31: [select] | D31: [select] | E31: [select]
C32: LPG (N/A) | D32: None | E32: None
C33: Nat Gas/Diesel Boiler - Large (>100 GJ/hr or >30MW) | D33: Cyclone | E33: Selective Catalyctic Reduction
C34: Nat Gas/Diesel Boiler - Small (<100 GJ/hr or <30MW) | D34: Cyclone (high efficiency) | E34: Water / Steam Injection
C35: Coal PC Drybottom | D35: Cyclone (high throughput) | E35: Air / Fuel Ratio: n/a
C36: Coal PC Wetbottom | D36: Electostatic precipitator | E36: Air / Fuel Ratio: + 3%
C37: Coal Cyclone | D37: ESP with carbon injection | E37: Air / Fuel Ratio: +/- 10%
C38: Coal FBC Circulating | D38: ESP with polishing wet scrubber | E38: Injection Rate Setting: n/a
C39: Coal FBC Bubbling | D39: Fabric filter | E39: Injection Rate Setting: + 0%
C40: Coal Spreader Stocker | D40: Fabric filter with carbon injection | E40: Injection Rate Setting: + 10%
C41: Coal Overfeed Stocker | D41: Fabric filter with polishing wet scrubber | E41: Injection Rate Setting: + 20%
C42: Coal Underfeed Stocker | D42: Fabric filter with spray absorbers (absorbent) | E42: Injection Rate Setting: + 30%
D43: Fabric filter with spray absorbers (limestone) | E43: Injection Timing Retard: Controlled
D44: Low excess air | E44: Injection Timing Retard: Uncontrolled
D45: Low NOX burner (air staged) | E45: Injection Timing Retard: 2C
D46: Low NOx burner (flue gas recirculation) | E46: Injection Timing Retard: + 4C
D47: Low NOX burner (fuel staged) | E47: Injection Timing Retard: + 8C
...

Sheet CWF-Plant and Equipment-Diesel
C3: Ravenswood Operations | H3: This tab captures fuel use and dust emissions from vehicles and unmetered engines
C4: 01/07/2023 - 30/06/2024 | H4: Once you have the fuel database data from Carole, group similar equipment using the identifiers in column E (GB Classification), then create a pivot table to determine the fuel use for each group. Update the values in red.
C6: Diesel Usage and Operational Data by Engine Class
H8: Data Sources: | K8: Fuel Database - Email Carole for data dump.
C9: Engines
C10: (1) Smooth roads are typically sealed and well-formed unsealed roads, while rough roads are any poorly-formed unsealed roads and steep/poorly graded tracks.
K11: Monthly Diesel Fuel Combustion | X11: % Use on Site | Y11: Number of Vehicles
C12: Class of Vehicle (1) | D12: Owned / Contractor Name | E12: GB Classification | G12: FY2023 Fuel | H12: FY2024 Fuel | I12: Unit | K12: Jul | L12: Aug | M12: Sep | N12: Oct | O12: Nov | P12: Dec | Q12: Jan | R12: Feb | S12: Mar | T12: Apr | U12: May | V12: Jun | X12: % Use on Site
C13: Bobcat | E13: RAV Vehicles (Bobcat) | G13: 0 | H13: =SUM(K13:V13) -> 0 | I13: L | X13: 100 | Y13: FILL OUT
C14: Bus | E14: RAV Vehicles (Bus) | G14: 17155.8 | H14: =SUM(K14:V14) -> 16712.62 | I14: L | K14: 967.58 | L14: 1636.63 | M14: 1529.01 | N14: 831.15 | O14: 1671.68 | P14: 1127.18 | Q14: 1304.29 | R14: 1897.36 | S14: 1897.36 | T14: 2140.7 | U14: 1709.68 | X14: 100 | Y14: FILL OUT
C15: Bogger | E15: RAV Vehicles (Bogger) | G15: 0 | H15: =SUM(K15:V15) -> 0 | I15: L | X15: 100 | Y15: FILL OUT
C16: Compressor (<450kW) | E16: RAV Vehicles (Compressor) | G16: 3348.1687 | H16: =SUM(K16:V16) -> 2191.3 | I16: L | K16: 410 | L16: 120 | M16: 227.1 | N16: 298.4 | O16: 164.1 | P16: 263.8 | Q16: 335.1 | R16: 46.6 | S16: 46.6 | T16: 154.2 | U16: 125.4 | X16: 100 | Y16: FILL OUT
C17: Concrete/Shotcrete Truck | E17: RAV Vehicles (Concrete Truck) | G17: 0 | H17: =SUM(K17:V17) -> 0 | I17: L | X17: 100 | Y17: FILL OUT
C18: Crane | E18: RAV Vehicles (Crane) | G18: 13362.2 | H18: =SUM(K18:V18) -> 2900.09 | I18: L | L18: 212.33 | O18: 220.47 | P18: 306.06 | Q18: 398.6 | R18: 372.5 | S18: 372.5 | T18: 590.75 | U18: 426.88 | X18: 79 | Y18: FILL OUT
C19: Dozer (Track Type) | E19: RAV Vehicles (Dozer - Tracked) | G19: 1854472.5 | H19: =SUM(K19:V19) -> 1831486 | I19: L | K19: 165650.8 | L19: 134663.87 | M19: 148848.1 | N19: 168020.58 | O19: 164213.5 | P19: 153484.4 | Q19: 144452.6 | R19: 108971.2 | S19: 108971.2 | T19: 166448.9 | U19: 167775.27 | V19: 199985.58 | X19: 100 | Y19: FILL OUT
C20: Drill (Surface) (<450kW) | E20: RAV Vehicles (Drill - Surface) | G20: 369693.68 | H20: =SUM(K20:V20) -> 1346935.9 | I20: L | K20: 110288.88 | L20: 108646.96 | M20: 130131.5 | N20: 163429.95 | O20: 185127.87 | P20: 136631.71 | Q20: 144961.78 | R20: 153111.94 | S20: 153111.94 | T20: 45353.84 | U20: 13136.64 | V20: 3002.84 | X20: 100 | Y20: FILL OUT
C21: EWP | E21: RAV Vehicles (EWP) | G21: 430 | H21: =SUM(K21:V21) -> 35 | I21: L | Q21: 35 | X21: 100 | Y21: FILL OUT
C22: Excavator (<450kW) | E22: RAV Vehicles (Excavator <450kW) | G22: 5123188 | H22: =SUM(K22:V22) -> 4371536.5 | I22: L | K22: 358694.2 | L22: 348509.6 | M22: 436572.82 | N22: 385985.09 | O22: 426102.76 | P22: 405860.5 | Q22: 374098.48 | R22: 234758.72 | S22: 234758.72 | T22: 389546.15 | U22: 357497.7 | V22: 419151.8 | X22: 100 | Y22: FILL OUT
C23: Excavator (>450kW) | E23: RAV Vehicles (Excavator >450kW) | G23: 0 | H23: =SUM(K23:V23) -> 0 | I23: L | X23: 100 | Y23: FILL OUT
C24: Forklift | E24: RAV Vehicles (Forklift) | G24: 13785.338 | H24: =SUM(K24:V24) -> 20453.9 | I24: L | K24: 4094.07 | L24: 1101.64 | M24: 3564.6 | N24: 6964.22 | O24: 725.43 | P24: 531.4 | Q24: 551.44 | R24: 863.77 | S24: 863.77 | T24: 356.17 | U24: 595.39 | V24: 242 | X24: 100 | Y24: FILL OUT
C25: Field Generator (<450kW) | E25: RAV Vehicles (Generator <500kW <100,000 kWhrs) | G25: 1746424.7 | H25: =SUM(K25:V25) -> 123839.89 | I25: L | K25: 10997.7 | L25: 9976.3 | M25: 6076.9 | N25: 11992.095 | O25: 8355.1 | P25: 5399 | Q25: 15542.8 | R25: 3721.9 | S25: 3721.9 | T25: 21801.2 | U25: 21245.1 | V25: 5009.9 | X25: 100 | Y25: FILL OUT
C26: Field Generator (>500kW) | E26: RAV vehicle (Power Plant Generator) | G26: 12697371 | H26: =SUM(K26:V26) -> 25288078 | I26: L | K26: 1937868 | L26: 1520480 | M26: 1971468 | N26: 2463846 | O26: 2192819 | P26: 2308483 | Q26: 1996950 | R26: 2036285 | S26: 2036285 | T26: 2420764 | U26: 2054270 | V26: 2348560 | X26: 100 | Y26: FILL OUT
C27: Grader | E27: RAV Vehicles (Grader) | G27: 197596.11 | H27: =SUM(K27:V27) -> 252404.48 | I27: L | K27: 20211.08 | L27: 17050.9 | M27: 19690.91 | N27: 22161.46 | O27: 24337.44 | P27: 24008.91 | Q27: 21649.7 | R27: 14714.1 | S27: 14714.1 | T27: 22296.38 | U27: 25653.7 | V27: 25915.8 | X27: 100 | Y27: FILL OUT
C28: Haul/Dump Truck | E28: RAV Vehicles (Haul Truck) | G28: 11874044 | H28: =SUM(K28:V28) -> 13008539 | I28: L | K28: 1025675 | L28: 931880.82 | M28: 923727.52 | N28: 958782.68 | O28: 989826.61 | P28: 1099107.4 | Q28: 946960.48 | R28: 1292265.2 | S28: 1292265.2 | T28: 1196069.4 | U28: 1170660.2 | V28: 1181318.3 | X28: 100 | Y28: FILL OUT
C29: IT Loader | E29: RAV Vehicles (IT Loader) | G29: 22383.53 | H29: =SUM(K29:V29) -> 6984.26 | I29: L | K29: 175.43 | L29: 611.35 | M29: 503.42 | N29: 770.14 | O29: 730.31 | P29: 699.15 | Q29: 767.44 | R29: 867.31 | S29: 867.31 | T29: 340.39 | U29: 612.01 | V29: 40 | X29: 100 | Y29: FILL OUT
C30: Light Truck | E30: RAV Vehicles (Light Truck) | G30: 156358.59 | H30: =SUM(K30:V30) -> 78855.75 | I30: L | K30: 3526.26 | L30: 6886 | M30: 4485.7 | N30: 10148.7 | O30: 11903.14 | P30: 7511.59 | Q30: 9100.46 | R30: 8561.09 | S30: 8561.09 | T30: 3875.2 | U30: 3928.73 | V30: 367.79 | X30: 84 | Y30: FILL OUT
C31: Light Vehicle | E31: RAV Vehicles (Light Vehicle Post-2004) | G31: 605301.85 | H31: =SUM(K31:V31) -> 399646.61 | I31: L | K31: 32090.63 | L31: 33693.13 | M31: 25097.36 | N31: 26147.15 | O31: 38377.12 | P31: 32615.78 | Q31: 32033.51 | R31: 30893.66 | S31: 30893.66 | T31: 35159.77 | U31: 73818.92 | V31: 8825.92 | X31: 77 | Y31: FILL OUT
C32: Lighting Plant (<450kW) | E32: RAV Vehicles (Lighting Plant) | G32: 42579.37 | H32: =SUM(K32:V32) -> 79940.35 | I32: L | K32: 4768.43 | L32: 5029.3 | M32: 7687.16 | N32: 6023.17 | O32: 4119.06 | P32: 9623.1 | Q32: 4356.8 | R32: 11309.46 | S32: 11309.46 | T32: 5123.01 | U32: 5712.1 | V32: 4879.3 | X32: 100 | Y32: FILL OUT
C33: Loader (Wheeled) | E33: RAV Vehicles (Loader - Wheeled) | G33: 2691730.3 | H33: =SUM(K33:V33) -> 2076974.7 | I33: L | K33: 191998.35 | L33: 154583.36 | M33: 153321.23 | N33: 163542.29 | O33: 153620.26 | P33: 200962.94 | Q33: 187186.68 | R33: 120877.69 | S33: 120877.69 | T33: 203894.95 | U33: 214987.36 | V33: 211121.88 | X33: 100 | Y33: FILL OUT
C34: Mobile Screen (<450kW) | E34: RAV Vehicles (Mobile Screen) | G34: 97.5 | H34: =SUM(K34:V34) -> 0 | I34: L | X34: 100 | Y34: FILL OUT
C35: Mobile Stacker (<450kW) | E35: RAV Vehicles (Mobile Stacker) | G35: 273.33 | H35: =SUM(K35:V35) -> 0 | I35: L | X35: 100 | Y35: FILL OUT
C36: Mobile Crusher (<450kW) | E36: RAV Vehicles (Mobiler Crusher) | G36: 133063.65 | H36: =SUM(K36:V36) -> 0 | I36: L | X36: 100 | Y36: FILL OUT
C37: Pump (<450kW) | E37: RAV Vehicles (Pump <450kW) | G37: 101409.93 | H37: =SUM(K37:V37) -> 195822.3 | I37: L | K37: 6277.7 | L37: 11327 | M37: 5469.3 | N37: 21500.7 | O37: 30517.7 | P37: 34809.6 | Q37: 10695.3 | T37: 7930 | U37: 49263 | V37: 18032 | X37: 100 | Y37: FILL OUT
C38: Road Train | E38: RAV Vehicles (Road Train) | G38: 0 | H38: =SUM(K38:V38) -> 0 | I38: L | X38: 100 | Y38: FILL OUT
C39: Roller | E39: RAV Vehicles (Roller) | G39: 62659.702 | H39: =SUM(K39:V39) -> 100202.86 | I39: L | K39: 3350.92 | L39: 3150.73 | M39: 4169.98 | N39: 19032.954 | O39: 11283.21 | P39: 7653.38 | Q39: 8104.15 | R39: 9207.76 | S39: 9207.76 | T39: 14718.32 | U39: 6885.7 | V39: 3438 | X39: 100 | Y39: FILL OUT
C40: Scraper | E40: RAV Vehicles (Scraper) | G40: 213383.48 | H40: =SUM(K40:V40) -> 433620.13 | I40: L | K40: 36724 | L40: 21975.374 | M40: 52025 | N40: 53908.868 | O40: 49942.82 | P40: 25871.87 | Q40: 22854.15 | R40: 43493.82 | S40: 43493.82 | T40: 63331.72 | U40: 18289.69 | V40: 1709 | X40: 100 | Y40: FILL OUT
C41: Service Truck | E41: RAV Vehicles (Service Truck) | G41: 218885.97 | H41: =SUM(K41:V41) -> 0 | I41: L | X41: 100 | Y41: FILL OUT
C42: Tractor | E42: RAV Vehicles (Tractor) | G42: 1393.84 | H42: =SUM(K42:V42) -> 1801.06 | I42: L | M42: 46.96 | N42: 245.63 | O42: 128.07 | P42: 134.66 | Q42: 252.43 | R42: 209.28 | S42: 209.28 | T42: 256.08 | U42: 318.67 | X42: 100 | Y42: FILL OUT
C43: Unspecified | E43: RAV Vehicles (Unspecified) | G43: 85269.87 | H43: =SUM(K43:V43) -> 544093.36 | I43: L | K43: 619.32 | L43: 116026.99 | M43: 155175.47 | N43: 189.5 | O43: 874.4 | P43: 132841.58 | Q43: 15490.72 | R43: 45275.33 | S43: 45275.33 | T43: 8869.26 | U43: 13816.03 | V43: 9639.43 | X43: 100 | Y43: FILL OUT
C44: Water Cart | E44: RAV Vehicles (Water Cart) | G44: 0 | H44: =SUM(K44:V44) -> 180150.49 | I44: L | K44: 10058.85 | L44: 8766.48 | M44: 16423.27 | N44: 14487.1 | O44: 20618.49 | P44: 16461.31 | Q44: 17697.98 | R44: 15725.8 | S44: 15725.8 | T44: 20732.56 | U44: 17315.75 | V44: 6137.1 | X44: 100 | Y44: FILL OUT
...

Sheet CWF - Plant and Equipment-Other
C3: Ravenswood Operations | G3: This tab captures fuel use and dust emissions from vehicles and unmetered engines using fuel other than diesel
C4: 01/07/2023 - 30/06/2024 | G4: Greenbase will estimate the kilometres travelled if this information is unable to be provided
C6: Other Fuel Usage and Operational Data by Engine Class | G6: Request from Carole. If you cannot find the monthly invoices, go to the Post Office and ask to take photos of their log book. This will show monthly fuel issues for RG.
J8: Data Sources: | L8: Monthly invoices from Ravenswood Post Office (Julie/Carole)
C9: Other Fuels
L10: Monthly Other Fuel Consumption | Y10: % Use on Site
C11: Class of Vehicle (1) | D11: Owner | E11: Model | F11: Fuel Type | G11: Unit | I11: FY2023 Fuel | J11: FY2024 Fuel | L11: Jul | M11: Aug | N11: Sep | O11: Oct | P11: Nov | Q11: Dec | R11: Jan | S11: Feb | T11: Mar | U11: Apr | V11: May | W11: Jun | Y11: % Use on Site
C12: Light Vehicle | D12: NOL | E12: Light Vehicles | F12: ULP | G12: L | I12: 5599.1 | J12: =SUM(L12:W12) -> 4964.8 | L12: 391.3 | M12: 430.9 | N12: 501.4 | O12: 630.5 | P12: 457.3 | Q12: 389.2 | R12: 518.9 | S12: 364.5 | T12: 346.3 | U12: 420.2 | V12: 175.6 | W12: 338.7 | Y12: 80
C13: Compressor | D13: Enviro | E13: Honda | F13: ULP | G13: L | I13: 8.7 | J13: =SUM(L13:W13) -> 167.3 | Q13: 39.2 | S13: 73.3 | T13: 54.8 | Y13: 20
C14: Ancillary (Other) | D14: NOL | E14: Mowers, LV workshop (compressor) | F14: ULP | G14: L | I14: 1921.3 | J14: =SUM(L14:W14) -> 0 | Y14: 100
C15: Bus | D15: NOL | F15: [select] | G15: [select] | J15: =SUM(L15:W15) -> 937.5 | L15: 74 | M15: 53 | N15: 39 | O15: 117.5 | P15: 76.8 | Q15: 129.7 | R15: 93.5 | S15: 50 | T15: 96.1 | U15: 111.9 | V15: 49.9 | W15: 46.1 | Y15: 100
C16: [select] | F16: [select] | G16: [select] | J16: =SUM(L16:W16) -> 0 | Y16: 100
C18: Kilometres Travelled | D18: Greenbase will estimate the kilometres travelled if this information is unable to be provided
L19: Work Area | M19: STEP 1 % In Pit | N19: STEP 2 % Underground | O19: STEP 3 % Sealed | P19: % Surface and Unpaved | Q19: Mean Vehicle Weight | R19: Fuel Burn Rate | S19: Average Vehicle Speed
C20: Class of Vehicle | D20: Owner | E20: Model | I20: FY2023 Distance | J20: FY2024 Distance
I21: km | J21: km | L21: Option | M21: % | N21: % | O21: % | P21: % | Q21: Tonne | R21: km/L | S21: km/hr
C22: Light Vehicle | D22: NOL | E22: Light Vehicles | I22: 27995.5 | J22: =J12*R22 -> 24824 | L22: Roads and Access Tracks | M22: 0 | N22: 0 | O22: 60 | P22: =100-M22-N22-O22 -> 40 | Q22: =IF($C22="[select]","Select Vehicle Class",IF($C22="light vehicle","NA",IF($C22="grader","NA","Please enter"))) -> NA | R22: 5 | S22: 50
C23: Bus | L23: [select] | M23: 0 | N23: 0 | O23: 0 | P23: =100-M23-N23-O23 -> 100 | Q23: =IF($C23="[select]","Select Vehicle Class",IF($C23="light vehicle","NA",IF($C23="grader","NA","Please enter"))) -> Please enter | S23: =IF($C23="[select]","Select Vehicle Class",IF($C23="light vehicle","Please enter",IF($C23="grader","Please enter","NA"))) -> NA
C24: [select] | L24: [select] | M24: 0 | N24: 0 | O24: 0 | P24: =100-M24-N24-O24 -> 100 | Q24: =IF($C24="[select]","Select Vehicle Class",IF($C24="light vehicle","NA",IF($C24="grader","NA","Please enter"))) -> Select Vehicle Class | S24: =IF($C24="[select]","Select Vehicle Class",IF($C24="light vehicle","Please enter",IF($C24="grader","Please enter","NA"))) -> Select Vehicle Class
C26: Vehicle Class | D26: Dust Sources | E26: Required Variables | L26: Parameter | N26: Description
C27: [select]
C28: Aircraft | D28: No
C29: Ancillary (Other) | D29: Movement, if applicable | E29: Work Area, Distance Travelled, % in Locations, Weights | L29: Owner: | N29: Owner of the fleet, i.e. your company or contractor name
C30: Backhoe | D30: No | L30: Model: | N30: Vehicle model name, i.e. Cat 657
C31: Bobcat | D31: No | L31: No Of: | N31: Number of type and model belonging to owner
C32: Bus | D32: Movement | E32: Work Area, Distance Travelled, % in Locations, Weights | L32: Gross Weight: | N32: Fully loaded weight of vehicle
C33: Cars
C34: Commercial (Rough Roads) | D34: Movement | E34: Work Area, Distance Travelled, % in Locations, Weights | L34: Op Hrs: | N34: Total operating hours for period
C35: Commercial MGV (Smooth Roads)
C36: Commercial HGV (Smooth Roads)
C37: Crane | D37: No | L37: Kilometres Travelled: | N37: Total distance travelled for period
C38: EWP | D38: No | L38: % Sealed, In Pit, UG and Surface | N38: This info is required because vehicles used in the pit, underground or sealed have a reduced dust emission factor
C39: Forklift | D39: No
C40: Grader | D40: Movement | E40: Distance Travelled, % in Locations
C41: Heaters and BBQs | D41: No
C42: IT Loader | D42: No
C43: Jumbo | D43: No
C44: Light Vehicle (Rough Roads) | D44: Movement | E44: Work Area, Distance Travelled, % in Locations, Weights
C45: Light Vehicle (Smooth Roads)
C46: Tractor | D46: No
...

Sheet ES - Drilling and Explosives
C3: Ravenswood Operations | G3: If area blasted is unavailable, an appropriate approximation is BCM divided by average bench height
C4: 01/07/2023 - 30/06/2024 | G4: If count is selected for units option, please specify unit size.
C6: Drilling and Blasting | G6: Data for Drill and Blast is saved in the pink tab (Yearly Pollution and greenhouse) in G:\Environment\16. SHE Monitoring, Measuring and Reporting\Monitoring\Blast monitoring\2024\Drill database V13-Shortcut . You will need to get Grade Control data from AJ Koen and Exploration data from Steve Harper.
C8: Blasting
C10: Explosives | K10: Data Sources: | M10: Sourced from Mining Department (Drill and Blast Engineers), Mining Geology (Grade Control), Exploration
C12: Mine Name | D12: Product Name | F12: Supplier | G12: Fuel % If Applicable | H12: Explosive batched onsite? | I12: Hole Dia (> or < 152mm) | J12: FY2023 Amount | K12: FY2024 Amount | L12: Unit | M12: Monthly Amount
D13: Explosive Type | E13: Commercial Name | M13: Jul | N13: Aug | O13: Sep | P13: Oct | Q13: Nov | R13: Dec | S13: Jan | T13: Feb | U13: Mar | V13: Apr | W13: May | X13: Jun
C14: Buck Reef West and Sarsfield | D14: Emulsion/ANFO blend | E14: Fortis Eclipse 1.1 | F14: Orica | G14: 1 | H14: Yes | I14: <152mm | J14: 7098.576 | K14: =SUM(M14:X14) -> 6595.446 | L14: tonnes | M14: 609.472 | N14: 547.351 | O14: 566.13 | P14: 645.774 | Q14: 837.437 | R14: 524.644 | S14: 434.849 | T14: 386.9 | U14: 475.38 | V14: 561.485 | W14: 446.089 | X14: 559.935
C16: Mine Name | D16: Product Name | F16: Supplier | G16: Fuel % If Applicable | H16: Explosive batched onsite? | I16: Hole Dia (> or < 152mm) | J16: FY2023 Amount | K16: FY2024 Amount | L16: Unit | M16: Monthly Amount
D17: Explosive Type | E17: Commercial Name | M17: Jul | N17: Aug | O17: Sep | P17: Oct | Q17: Nov | R17: Dec | S17: Jan | T17: Feb | U17: Mar | V17: Apr | W17: May | X17: Jun
H18: [select] | I18: [select] | J18: - | K18: =SUM(M18:X18) -> 0 | L18: [select]
H19: [select] | I19: [select] | K19: =SUM(M19:X19) -> 0 | L19: [select]
H20: [select] | I20: [select] | K20: =SUM(M20:X20) -> 0 | L20: [select]
H22: Total ANFO Doped Emulsion | K22: =SUM(M22:X22) -> 0 | L22: [select] | M22: =SUM(M18:M20) -> 0 | N22: =SUM(N18:N20) -> 0 | O22: =SUM(O18:O20) -> 0 | P22: =SUM(P18:P20) -> 0 | Q22: =SUM(Q18:Q20) -> 0 | R22: =SUM(R18:R20) -> 0 | S22: =SUM(S18:S20) -> 0 | T22: =SUM(T18:T20) -> 0 | ... X22: =SUM(X18:X20) -> 0
C24: Drill and Blast
C26: Open Cut Name | E26: Parameter | I26: Material Assay | J26: FY2023 Amount | K26: FY2024 Amount | L26: Unit | M26: Monthly Amount
M27: Jul | N27: Aug | O27: Sep | P27: Oct | Q27: Nov | R27: Dec | S27: Jan | T27: Feb | U27: Mar | V27: Apr | W27: May | X27: Jun
C28: Buck Reef West and Sarsfield | E28: Total surface area blasted | I28: BRW Ore Assay | J28: 877569 | K28: =SUM(M28:X28) -> 829659.5 | L28: m2 | M28: 81858.576 | N28: 74693.064 | O28: 73856.589 | P28: 91433.683 | Q28: 107105.78 | R28: 72448.44 | S28: 43610.75 | T28: 49290.152 | U28: 63955.435 | V28: 54800.584 | W28: 57765.376 | X28: 58841.071
E29: Number of blast events | J29: 179 | K29: =SUM(M29:X29) -> 199 | L29: count | M29: 16 | N29: 15 | O29: 18 | P29: 18 | Q29: 16 | R29: 21 | S29: 17 | T29: 13 | U29: 17 | V29: 17 | W29: 18 | X29: 13
E30: Number of holes drilled | J30: 103451 | K30: =SUM(M30:X30) -> 98273 | L30: count | M30: 10213 | N30: 8508 | O30: 7663 | P30: 10367 | Q30: 10913 | R30: 7947 | S30: 5954 | T30: 6022 | U30: 7051 | V30: 7383 | W30: 8265 | X30: 7987
E31: Drilling in pit | J31: 100 | L31: %
E32: Water Sprays used for drilling | J32: No | K32: [select] | L32: option
E33: Dust Collector used for drilling (Fabric Filter) | J33: Yes | K33: [select] | L33: option
E34: Moisture Content of Pit | J34: 2 | L34: %
C37: Drilling for On-Site Grade Control and Resource Definition
C39: Area Name | E39: Parameter | I39: Material Assay | J39: FY2023 Value | K39: FY2024 Value | L39: Unit | M39: Monthly Amount
M40: Jul | N40: Aug | O40: Sep | P40: Oct | Q40: Nov | R40: Dec | S40: Jan | T40: Feb | U40: Mar | V40: Apr | W40: May | X40: Jun
C41: BRW (Grade Control) | E41: Number of holes drilled | I41: BRW Ore Assay | J41: 5094 | K41: =SUM(M41:X41) -> 3654 | L41: count | M41: 281 | N41: 329 | O41: 464 | P41: 454 | Q41: 427 | R41: 312 | S41: 193 | T41: 343 | U41: 258 | V41: 130 | W41: 323 | X41: 140
E42: Drilling on site | J42: 100 | L42: %
E43: Drilling in pit | J43: 0 | L43: %
E44: Dust collection hopper (cyclone) used | J44: Yes | K44: [select] | L44: option
E45: Water Sprays used for drilling | J45: Yes | K45: [select] | L45: option
E46: Dust Collector used for drilling (Fabric Filter) | J46: Yes | K46: [select] | L46: option
C48: Area Name | E48: Parameter | I48: Material Assay | J48: FY2023 Value | K48: FY2024 Value | L48: Unit | M48: Monthly Amount
M49: Jul | N49: Aug | O49: Sep | P49: Oct | Q49: Nov | R49: Dec | S49: Jan | T49: Feb | U49: Mar | V49: Apr | W49: May | X49: Jun
C50: Sarsfield (Grade Control) | E50: Number of holes drilled | I50: Sarsfield Combined Ore Assay | J50: 5094 | K50: =SUM(M50:X50) -> 625 | L50: count | M50: 0 | N50: 0 | O50: 45 | P50: 32 | Q50: 6 | R50: 28 | S50: 76 | T50: 19 | U50: 102 | V50: 173 | W50: 32 | X50: 112
E51: Drilling on site | J51: 100 | L51: %
E52: Drilling in pit | J52: 0 | L52: %
E53: Dust collection hopper (cyclone) used | J53: Yes | K53: [select] | L53: option
E54: Water Sprays used for drilling | J54: Yes | K54: [select] | L54: option
...

Sheet Geology
C3: Ravenswood Operations | G3: Rock and soil assays
C4: 01/07/2023 - 30/06/2024 | G4: If a substance is not detected please enter the detection limit
G5: If no value supplied, Greenbase are obliged to use Table 9 from the Mining Manual to fill in any gaps (see screenshot below).
C7: Geology | E7: Data Source: | F7: Total Metal Analysis - data from DataSight
C9: Type | D9: Name | E9: Assay Date | F9: Substance and Units
F10: As | G10: B | H10: Be | I10: Cd | J10: Co | K10: Cr | L10: Cr (III) | M10: Cu | N10: F | O10: Hg | P10: Mn | Q10: Ni | R10: Pb | S10: Sb | T10: Se | U10: Zn
F11: mg/kg | G11: mg/kg | H11: mg/kg | I11: mg/kg | J11: mg/kg | K11: mg/kg | L11: mg/kg | M11: mg/kg | N11: mg/kg | O11: mg/kg | P11: mg/kg | Q11: mg/kg | R11: mg/kg | S11: mg/kg | T11: mg/kg | U11: mg/kg
C12: Road Assay | D12: Combined Road | E12: Average | F12: 67.476 | G12: 10 | H12: 0.3 | I12: 0.902 | J12: 2.6 | K12: 4.571 | L12: 4.571 | M12: 234.238 | N12: 200 | O12: 0.025 | P12: 950 | Q12: 6.667 | R12: 5.452 | S12: 0.2 | T12: 1.5 | U12: 70
C13: Topsoil Assay | D13: Average Topsoil Assay | E13: Average | F13: 4.8333 | G13: 20 | H13: 0.4333 | I13: 0.45 | J13: 9 | K13: 26.3333 | L13: 26.3333 | M13: 35.6667 | N13: 190 | O13: 0.0533 | P13: 638.6667 | Q13: 19.6667 | R13: 13.3333 | S13: 1.7333 | T13: 1.6833 | U13: 46.3333
C14: Ore Assay | D14: Average Ore Assay | E14: Average | F14: 81.0625 | G14: 19.375 | H14: 0.6875 | I14: 1.6375 | J14: 21.8125 | K14: 7.75 | L14: 7.75 | M14: 463.75 | N14: 571.25 | O14: 0.05 | P14: 1225.625 | Q14: 9.125 | R14: 25.8188 | S14: 2.5188 | T14: 2.2188 | U14: 240.25
